<?xml version="1.0"?>
<robot name="xarm7">
  <link name="link_base">
    <inertial>
      <origin xyz="-0.021131 -0.0016302 0.056488" rpy="0 0 0" />
      <mass value="0.88556" />
      <inertia
        ixx="0.0030595" ixy="0.00012259" ixz="-0.00062705"
        iyy="0.0037783" iyz="0.00027023" izz="0.0020125" />
    </inertial>
    <visual>
      <origin xyz="0 0 0" rpy="0 0 0"/>
      <geometry>
        <mesh filename="meshes/visual/link_base.stl"/>
      </geometry>
      <material name="White"/>
    </visual>
    <collision>
      <origin xyz="0 0 0" rpy="0 0 0"/>
      <geometry>
        <mesh filename="meshes/visual/link_base.stl"/>
      </geometry>
    </collision>
  </link>
  
  <link name="link1">
    <inertial>
      <origin xyz="0 0 0" rpy="0 0 0" />
      <!-- Assuming default inertial parameters -->
      <mass value="2.16"/>
      <inertia
        ixx="0.00952" ixy="0" ixz="0"
        iyy="0.00952" iyz="0" izz="0.00563" />
    </inertial>
    <visual>
      <origin xyz="0 0 0" rpy="0 0 0"/>
      <geometry>
        <mesh filename="meshes/visual/link1.stl"/>
      </geometry>
      <material name="White"/>
    </visual>
    <collision>
      <origin xyz="0 0 0" rpy="0 0 0"/>
      <geometry>
        <mesh filename="meshes/visual/link1.stl"/>
      </geometry>
    </collision>
  </link>
  
  <joint name="joint1" type="revolute">
    <origin xyz="0 0 0.267" rpy="0 0 0" />
    <parent link="link_base" />
    <child link="link1" />
    <axis xyz="0 0 1" />
    <limit
      lower="-6.28318530718"
      upper="6.28318530718"
      effort="50"
      velocity="3.14" />
    <dynamics damping="10" friction="1" />
  </joint>
  
  <link name="link2">
    <inertial>
      <origin xyz="0 0 0" rpy="0 0 0" />
      <!-- Assuming default inertial parameters -->
      <mass value="2.10"/>
      <inertia
        ixx="0.00952" ixy="0" ixz="0"
        iyy="0.00952" iyz="0" izz="0.00563" />
    </inertial>
    <visual>
      <origin xyz="0 0 0" rpy="0 0 0"/>
      <geometry>
        <mesh filename="meshes/visual/link2.stl"/>
      </geometry>
      <material name="White"/>
    </visual>
    <collision>
      <origin xyz="0 0 0" rpy="0 0 0"/>
      <geometry>
        <mesh filename="meshes/visual/link2.stl"/>
      </geometry>
    </collision>
  </link>
  
  <joint name="joint2" type="revolute">
    <origin xyz="0 0 0" rpy="-1.5708 0 0" />
    <parent link="link1" />
    <child link="link2" />
    <axis xyz="0 0 1" />
    <limit
      lower="-2.059"
      upper="2.0944"
      effort="50"
      velocity="3.14" />
    <dynamics damping="10" friction="1" />
  </joint>
  
  <link name="link3">
    <inertial>
      <origin xyz="0 0 0" rpy="0 0 0" />
      <!-- Assuming default inertial parameters -->
      <mass value="1.73"/>
      <inertia
        ixx="0.00952" ixy="0" ixz="0"
        iyy="0.00952" iyz="0" izz="0.00563" />
    </inertial>
    <visual>
      <origin xyz="0 0 0" rpy="0 0 0"/>
      <geometry>
        <mesh filename="meshes/visual/link3.stl"/>
      </geometry>
      <material name="White"/>
    </visual>
    <collision>
      <origin xyz="0 0 0" rpy="0 0 0"/>
      <geometry>
        <mesh filename="meshes/visual/link3.stl"/>
      </geometry>
    </collision>
  </link>
  
  <joint name="joint3" type="revolute">
    <origin xyz="0 -0.293 0" rpy="1.5708 0 0" />
    <parent link="link2" />
    <child link="link3" />
    <axis xyz="0 0 1" />
    <limit
      lower="-6.28318530718"
      upper="6.28318530718"
      effort="30"
      velocity="3.14" />
    <dynamics damping="5" friction="1" />
  </joint>
  
  <link name="link4">
    <inertial>
      <origin xyz="0 0 0" rpy="0 0 0" />
      <!-- Assuming default inertial parameters -->
      <mass value="1.69"/>
      <inertia
        ixx="0.00952" ixy="0" ixz="0"
        iyy="0.00952" iyz="0" izz="0.00563" />
    </inertial>
    <visual>
      <origin xyz="0 0 0" rpy="0 0 0"/>
      <geometry>
        <mesh filename="meshes/visual/link4.stl"/>
      </geometry>
      <material name="White"/>
    </visual>
    <collision>
      <origin xyz="0 0 0" rpy="0 0 0"/>
      <geometry>
        <mesh filename="meshes/visual/link4.stl"/>
      </geometry>
    </collision>
  </link>
  
  <joint name="joint4" type="revolute">
    <origin xyz="0.0525 0 0" rpy="1.5708 0 0" />
    <parent link="link3" />
    <child link="link4" />
    <axis xyz="0 0 1" />
    <limit
      lower="-0.19198"
      upper="3.927"
      effort="30"
      velocity="3.14" />
    <dynamics damping="5" friction="1" />
  </joint>
  
  <link name="link5">
    <inertial>
      <origin xyz="0 0 0" rpy="0 0 0" />
      <!-- Assuming default inertial parameters -->
      <mass value="1.62"/>
      <inertia
        ixx="0.00952" ixy="0" ixz="0"
        iyy="0.00952" iyz="0" izz="0.00563" />
    </inertial>
    <visual>
      <origin xyz="0 0 0" rpy="0 0 0"/>
      <geometry>
        <mesh filename="meshes/visual/link5.stl"/>
      </geometry>
      <material name="White"/>
    </visual>
    <collision>
      <origin xyz="0 0 0" rpy="0 0 0"/>
      <geometry>
        <mesh filename="meshes/visual/link5.stl"/>
      </geometry>
    </collision>
  </link>
  
  <joint name="joint5" type="revolute">
    <origin xyz="0.0775 -0.3425 0" rpy="1.5708 0 0" />
    <parent link="link4" />
    <child link="link5" />
    <axis xyz="0 0 1" />
    <limit
      lower="-6.28318530718"
      upper="6.28318530718"
      effort="30"
      velocity="3.14" />
    <dynamics damping="5" friction="1" />
  </joint>
  
  <link name="link6">
    <inertial>
      <origin xyz="0 0 0" rpy="0 0 0" />
      <!-- Assuming default inertial parameters -->
      <mass value="1.29"/>
      <inertia
        ixx="0.00952" ixy="0" ixz="0"
        iyy="0.00952" iyz="0" izz="0.00563" />
    </inertial>
    <visual>
      <origin xyz="0 0 0" rpy="0 0 0"/>
      <geometry>
        <mesh filename="meshes/visual/link6.stl"/>
      </geometry>
      <material name="White"/>
    </visual>
    <collision>
      <origin xyz="0 0 0" rpy="0 0 0"/>
      <geometry>
        <mesh filename="meshes/visual/link6.stl"/>
      </geometry>
    </collision>
  </link>
  
  <joint name="joint6" type="revolute">
    <origin xyz="0 0 0" rpy="1.5708 0 0" />
    <parent link="link5" />
    <child link="link6" />
    <axis xyz="0 0 1" />
    <limit
      lower="-1.69297"
      upper="3.14159265359"
      effort="20"
      velocity="3.14" />
    <dynamics damping="2" friction="1" />
  </joint>
  
  <link name="link7">
    <inertial>
      <origin xyz="0 0 0" rpy="0 0 0" />
      <!-- Assuming default inertial parameters -->
      <mass value="0.25"/>
      <inertia
        ixx="0.00952" ixy="0" ixz="0"
        iyy="0.00952" iyz="0" izz="0.00563" />
    </inertial>
    <visual>
      <origin xyz="0 0 0" rpy="0 0 0"/>
      <geometry>
        <mesh filename="meshes/visual/link7.stl"/>
      </geometry>
      <material name="Silver"/>
    </visual>
    <collision>
      <origin xyz="0 0 0" rpy="0 0 0"/>
      <geometry>
        <mesh filename="meshes/visual/end_tool.stl"/>
      </geometry>
    </collision>
  </link>
  
  <joint name="joint7" type="revolute">
    <origin xyz="0.076 0.097 0" rpy="-1.5708 0 0" />
    <parent link="link6" />
    <child link="link7" />
    <axis xyz="0 0 1" />
    <limit
      lower="-6.28318530718"
      upper="6.28318530718"
      effort="20"
      velocity="3.14" />
    <dynamics damping="2" friction="1" />
  </joint>

<link name="link_eef">
    <visual>
      <geometry>
        <mesh filename="meshes/visual/d435_with_cam_stand.stl"/>
      </geometry>
      <origin rpy="0 0 0" xyz="0 0 0"/>
      <material name="Silver"/>
    </visual>
    <collision>
      <geometry>
        <mesh filename="meshes/visual/d435_with_cam_stand.stl"/>
      </geometry>
      <origin rpy="0 0 0" xyz="0 0 0"/>
    </collision>
  </link>
  <link name="camera_link"/>
  <link name="camera_depth_frame"/>
  <link name="camera_depth_optical_frame"/>
  <link name="camera_color_frame"/>
  <link name="camera_color_optical_frame"/>
  <link name="camera_left_ir_frame"/>
  <link name="camera_left_ir_optical_frame"/>
  <link name="camera_right_ir_frame"/>
  <link name="camera_right_ir_optical_frame"/>
  <joint name="camera_link_joint" type="fixed">
    <parent link="link_eef"/>
    <child link="camera_link"/>
    <origin rpy="3.141592653589793 -1.5707963267948966 0" xyz="0.06746 -0.0175 0.0237"/>
  </joint>
  <joint name="camera_depth_joint" type="fixed">
    <parent link="camera_link"/>
    <child link="camera_depth_frame"/>
    <origin rpy="0 0 0" xyz="0 0 0"/>
  </joint>
  <joint name="camera_depth_optical_joint" type="fixed">
    <parent link="camera_depth_frame"/>
    <child link="camera_depth_optical_frame"/>
    <origin rpy="-1.5707963267948966 0 -1.5707963267948966" xyz="0 0 0"/>
  </joint>
  <joint name="camera_color_joint" type="fixed">
    <parent link="camera_link"/>
    <child link="camera_color_frame"/>
    <origin rpy="0 0 0" xyz="0 0.015 0"/>
  </joint>
  <joint name="camera_color_optical_joint" type="fixed">
    <parent link="camera_color_frame"/>
    <child link="camera_color_optical_frame"/>
    <origin rpy="-1.5707963267948966 0 -1.5707963267948966" xyz="0 0 0"/>
  </joint>
  <joint name="camera_left_ir_joint" type="fixed">
    <parent link="camera_link"/>
    <child link="camera_left_ir_frame"/>
    <origin rpy="0 0 0" xyz="0 0 0"/>
  </joint>
  <joint name="camera_left_ir_optical_joint" type="fixed">
    <parent link="camera_left_ir_frame"/>
    <child link="camera_left_ir_optical_frame"/>
    <origin rpy="-1.5707963267948966 0 -1.5707963267948966" xyz="0 0 0"/>
  </joint>
  <joint name="camera_right_ir_joint" type="fixed">
    <parent link="camera_link"/>
    <child link="camera_right_ir_frame"/>
    <origin rpy="0 0 0" xyz="0 -0.050 0"/>
  </joint>
  <joint name="camera_right_ir_optical_joint" type="fixed">
    <parent link="camera_right_ir_frame"/>
    <child link="camera_right_ir_optical_frame"/>
    <origin rpy="-1.5707963267948966 0 -1.5707963267948966" xyz="0 0 0"/>
  </joint>

  <joint name="joint_eef" type="fixed">
    <origin rpy="0 0 0" xyz="0 0 0"/>
    <parent link="link7"/>
    <child link="link_eef"/>
  </joint>
  <joint name="gripper_fix" type="fixed">
    <parent link="link_eef"/>
    <child link="xarm_gripper_base_link"/>
    <origin rpy="0 0 0" xyz="0 0 0"/>
  </joint>
  <link name="xarm_gripper_base_link">
    <inertial>
      <origin rpy="0 0 0" xyz="-0.00065489 -0.0018497 0.048028"/>
      <mass value="0.54156"/>
      <inertia ixx="0.00047106" ixy="3.9292E-07" ixz="2.6537E-06" iyy="0.00033072" iyz="-1.0975E-05" izz="0.00025642"/>
    </inertial>
    <visual>
      <geometry>
        <mesh filename="meshes/visual/gripper_base_link.stl"/>
      </geometry>
      <origin rpy="0 0 0" xyz="0 0 0"/>
      <material name="White"/>
    </visual>
    <collision>
      <geometry>
        <mesh filename="meshes/visual/gripper_base_link.stl"/>
      </geometry>
      <origin rpy="0 0 0" xyz="0 0 0"/>
    </collision>
  </link>
  <link name="left_outer_knuckle">
    <inertial>
      <origin rpy="0 0 0" xyz="2.9948E-14 0.021559 0.015181"/>
      <mass value="0.033618"/>
      <inertia ixx="1.9111E-05" ixy="-1.8803E-17" ixz="-1.1002E-17" iyy="6.6256E-06" iyz="-7.3008E-06" izz="1.3185E-05"/>
    </inertial>
    <visual>
      <geometry>
        <mesh filename="meshes/visual/left_outer_knuckle.stl"/>
      </geometry>
      <origin rpy="0 0 0" xyz="0 0 0"/>
      <material name="Silver"/>
    </visual>
    <collision>
      <geometry>
        <mesh filename="meshes/visual/left_outer_knuckle.stl"/>
      </geometry>
      <origin rpy="0 0 0" xyz="0 0 0"/>
    </collision>
  </link>
  <joint name="drive_joint" type="revolute">
    <origin rpy="0 0 0" xyz="0 0.035 0.059098"/>
    <parent link="xarm_gripper_base_link"/>
    <child link="left_outer_knuckle"/>
    <axis xyz="1 0 0"/>
    <limit effort="50" lower="0" upper="0.85" velocity="2"/>
  </joint>
  <link name="left_finger">
    <inertial>
      <origin rpy="0 0 0" xyz="-2.4536E-14 -0.016413 0.029258"/>
      <mass value="0.048304"/>
      <inertia ixx="1.7493E-05" ixy="-4.2156E-19" ixz="6.9164E-18" iyy="1.7225E-05" iyz="4.6433E-06" izz="5.1466E-06"/>
    </inertial>
    <visual>
      <geometry>
        <mesh filename="meshes/visual/left_finger.stl"/>
      </geometry>
      <origin rpy="0 0 0" xyz="0 0 0"/>
      <material name="Silver"/>
    </visual>
    <collision>
      <geometry>
        <mesh filename="meshes/visual/left_finger.stl"/>
      </geometry>
      <origin rpy="0 0 0" xyz="0 0 0"/>
    </collision>
  </link>
  <joint name="left_finger_joint" type="revolute">
    <origin rpy="0 0 0" xyz="0 0.035465 0.042039"/>
    <parent link="left_outer_knuckle"/>
    <child link="left_finger"/>
    <axis xyz="-1 0 0"/>
    <limit effort="50" lower="0" upper="0.85" velocity="2"/>
    <mimic joint="drive_joint" multiplier="1" offset="0"/>
  </joint>
  <link name="left_inner_knuckle">
    <inertial>
      <origin rpy="0 0 0" xyz="1.86600784687907E-06 0.0220467847633621 0.0261334672830885"/>
      <mass value="0.0230125781256706"/>
      <inertia ixx="6.09490024271906E-06" ixy="6.06651326160071E-11" ixz="7.19102670500635E-11" iyy="6.01955084375188E-06" iyz="-2.75316812991721E-06" izz="5.07862004479903E-06"/>
    </inertial>
    <visual>
      <geometry>
        <mesh filename="meshes/visual/left_inner_knuckle.stl"/>
      </geometry>
      <origin rpy="0 0 0" xyz="0 0 0"/>
      <material name="Silver"/>
    </visual>
    <collision>
      <geometry>
        <mesh filename="meshes/visual/left_inner_knuckle.stl"/>
      </geometry>
      <origin rpy="0 0 0" xyz="0 0 0"/>
    </collision>
  </link>
  <joint name="left_inner_knuckle_joint" type="revolute">
    <origin rpy="0 0 0" xyz="0 0.02 0.074098"/>
    <parent link="xarm_gripper_base_link"/>
    <child link="left_inner_knuckle"/>
    <axis xyz="1 0 0"/>
    <limit effort="50" lower="0" upper="0.85" velocity="2"/>
    <mimic joint="drive_joint" multiplier="1" offset="0"/>
  </joint>
  <link name="right_outer_knuckle">
    <inertial>
      <origin rpy="0 0 0" xyz="-3.1669E-14 -0.021559 0.015181"/>
      <mass value="0.033618"/>
      <inertia ixx="1.9111E-05" ixy="-1.8789E-17" ixz="1.0986E-17" iyy="6.6256E-06" iyz="7.3008E-06" izz="1.3185E-05"/>
    </inertial>
    <visual>
      <geometry>
        <mesh filename="meshes/visual/right_outer_knuckle.stl"/>
      </geometry>
      <origin rpy="0 0 0" xyz="0 0 0"/>
      <material name="Silver"/>
    </visual>
    <collision>
      <geometry>
        <mesh filename="meshes/visual/right_outer_knuckle.stl"/>
      </geometry>
      <origin rpy="0 0 0" xyz="0 0 0"/>
    </collision>
  </link>
  <joint name="right_outer_knuckle_joint" type="revolute">
    <origin rpy="0 0 0" xyz="0 -0.035 0.059098"/>
    <parent link="xarm_gripper_base_link"/>
    <child link="right_outer_knuckle"/>
    <axis xyz="-1 0 0"/>
    <limit effort="50" lower="0" upper="0.85" velocity="2"/>
    <mimic joint="drive_joint" multiplier="1" offset="0"/>
  </joint>
  <link name="right_finger">
    <inertial>
      <origin rpy="0 0 0" xyz="2.5618E-14 0.016413 0.029258"/>
      <mass value="0.048304"/>
      <inertia ixx="1.7493E-05" ixy="-5.0014E-19" ixz="-7.5079E-18" iyy="1.7225E-05" iyz="-4.6435E-06" izz="5.1466E-06"/>
    </inertial>
    <visual>
      <geometry>
        <mesh filename="meshes/visual/right_finger.stl"/>
      </geometry>
      <origin rpy="0 0 0" xyz="0 0 0"/>
      <material name="Silver"/>
    </visual>
    <collision>
      <geometry>
        <mesh filename="meshes/visual/right_finger.stl"/>
      </geometry>
      <origin rpy="0 0 0" xyz="0 0 0"/>
    </collision>
  </link>
  <joint name="right_finger_joint" type="revolute">
    <origin rpy="0 0 0" xyz="0 -0.035465 0.042039"/>
    <parent link="right_outer_knuckle"/>
    <child link="right_finger"/>
    <axis xyz="1 0 0"/>
    <limit effort="50" lower="0" upper="0.85" velocity="2"/>
    <mimic joint="drive_joint" multiplier="1" offset="0"/>
  </joint>
  <link name="right_inner_knuckle">
    <inertial>
      <origin rpy="0 0 0" xyz="1.866E-06 -0.022047 0.026133"/>
      <mass value="0.023013"/>
      <inertia ixx="6.0949E-06" ixy="-6.0665E-11" ixz="7.191E-11" iyy="6.0197E-06" iyz="2.7531E-06" izz="5.0784E-06"/>
    </inertial>
    <visual>
      <geometry>
        <mesh filename="meshes/visual/right_inner_knuckle.stl"/>
      </geometry>
      <origin rpy="0 0 0" xyz="0 0 0"/>
      <material name="Silver"/>
    </visual>
    <collision>
      <geometry>
        <mesh filename="meshes/visual/right_inner_knuckle.stl"/>
      </geometry>
      <origin rpy="0 0 0" xyz="0 0 0"/>
    </collision>
  </link>
  <joint name="right_inner_knuckle_joint" type="revolute">
    <origin rpy="0 0 0" xyz="0 -0.02 0.074098"/>
    <parent link="xarm_gripper_base_link"/>
    <child link="right_inner_knuckle"/>
    <axis xyz="-1 0 0"/>
    <limit effort="50" lower="0" upper="0.85" velocity="2"/>
    <mimic joint="drive_joint" multiplier="1" offset="0"/>
  </joint>
  <link name="link_tcp"/>
  <joint name="joint_tcp" type="fixed">
    <origin rpy="0 0 0" xyz="0 0 0.18"/>
    <parent link="xarm_gripper_base_link"/>
    <child link="link_tcp"/>
  </joint>

  <!-- Materials -->
  <material name="White">
    <color rgba="1.0 1.0 1.0 1.0"/>
  </material>
  
  <material name="Silver">
    <color rgba="0.8 0.8 0.8 1.0"/>
  </material>
</robot>